Collecting tzdata (from django)
  Downloading tzdata-2024.2-py2.py3-none-any.whl (346 kB)
  Downloading tzdata-2024.2-py2.py3-none-any.whl (346 kB)
     ━━━━━━━━━━━━━━━━━━━━━━━━━━━━━━━━━━━━━━━━ 346.6/346.6 kB 21.0 MB/s eta 0:00:00
Installing collected packages: tzdata, sqlparse, asgiref, django
Successfully installed asgiref-3.8.1 django-5.1.5 sqlparse-0.5.3 tzdata-2024.2
Successfully installed asgiref-3.8.1 django-5.1.5 sqlparse-0.5.3 tzdata-2024.2

[notice] A new release of pip is available: 23.1.2 -> 24.3.1

[notice] A new release of pip is available: 23.1.2 -> 24.3.1
[notice] To update, run: python.exe -m pip install --upgrade pip
[notice] To update, run: python.exe -m pip install --upgrade pip
(.venv) PS C:\Users\51129532024.4\Desktop\curso-python\back-end\maquina_virtual> django-admin --version
(.venv) PS C:\Users\51129532024.4\Desktop\curso-python\back-end\maquina_virtual> django-admin --version
5.1.5
(.venv) PS C:\Users\51129532024.4\Desktop\curso-python\back-end\maquina_virtual> django-admin startproject senac
(.venv) PS C:\Users\51129532024.4\Desktop\curso-python\back-end\maquina_virtual> django-admin startproject senac
(.venv) PS C:\Users\51129532024.4\Desktop\curso-python\back-end\maquina_virtual> python manage.py runserver
(.venv) PS C:\Users\51129532024.4\Desktop\curso-python\back-end\maquina_virtual> python manage.py runserver
C:\Program Files\Python311\python.exe: can't open file 'C:\\Users\\51129532024.4\\Desktop\\curso-python\\back-end\\maquina_virtual\\manage.py': [Errno 2] No such file or directory
(.venv) PS C:\Users\51129532024.4\Desktop\curso-python\back-end\maquina_virtual> cd senac
(.venv) PS C:\Users\51129532024.4\Desktop\curso-python\back-end\maquina_virtual\senac> python manage.py runserver
Watching for file changes with StatReloader
Performing system checks...
Performing system checks...

System check identified no issues (0 silenced).

You have 18 unapplied migration(s). Your project may not work properly until you apply the migrations for app(s): admin, auth, contenttypes, sessions.

System check identified no issues (0 silenced).

You have 18 unapplied migration(s). Your project may not work properly until you apply the migrations for app(s): admin, auth, contenttypes, sessions.
Run 'python manage.py migrate' to apply them.
January 17, 2025 - 19:51:49
Run 'python manage.py migrate' to apply them.
January 17, 2025 - 19:51:49
Django version 5.1.5, using settings 'senac.settings'
Django version 5.1.5, using settings 'senac.settings'
Starting development server at http://127.0.0.1:8000/
Quit the server with CTRL-BREAK.

[17/Jan/2025 19:52:32] "GET / HTTP/1.1" 200 12068
Not Found: /favicon.ico
[17/Jan/2025 19:52:32] "GET /favicon.ico HTTP/1.1" 404 2207
(.venv) PS C:\Users\51129532024.4\Desktop\curso-python\back-end\maquina_virtual\senac> python manage.py runserver
Traceback (most recent call last):
  File "C:\Users\51129532024.4\Desktop\curso-python\back-end\maquina_virtual\.venv\Lib\site-packages\django\core\management\base.py", line 413, in run_from_argv
    self.execute(*args, **cmd_options)
  File "C:\Users\51129532024.4\Desktop\curso-python\back-end\maquina_virtual\.venv\Lib\site-packages\django\core\management\commands\runserver.py", line 75, in execute
    super().execute(*args, **options)
  File "C:\Users\51129532024.4\Desktop\curso-python\back-end\maquina_virtual\.venv\Lib\site-packages\django\core\management\base.py", line 459, in execute
    output = self.handle(*args, **options)
             ^^^^^^^^^^^^^^^^^^^^^^^^^^^^^
  File "C:\Users\51129532024.4\Desktop\curso-python\back-end\maquina_virtual\.venv\Lib\site-packages\django\core\management\commands\runserver.py", line 82, in handle
    if not settings.DEBUG and not settings.ALLOWED_HOSTS:
           ^^^^^^^^^^^^^^
  File "C:\Users\51129532024.4\Desktop\curso-python\back-end\maquina_virtual\.venv\Lib\site-packages\django\conf\__init__.py", line 81, in __getattr__
    self._setup(name)
  File "C:\Users\51129532024.4\Desktop\curso-python\back-end\maquina_virtual\.venv\Lib\site-packages\django\conf\__init__.py", line 68, in _setup
    self._wrapped = Settings(settings_module)
                    ^^^^^^^^^^^^^^^^^^^^^^^^^
  File "C:\Users\51129532024.4\Desktop\curso-python\back-end\maquina_virtual\.venv\Lib\site-packages\django\conf\__init__.py", line 166, in __init__
    mod = importlib.import_module(self.SETTINGS_MODULE)
          ^^^^^^^^^^^^^^^^^^^^^^^^^^^^^^^^^^^^^^^^^^^^^
  File "C:\Program Files\Python311\Lib\importlib\__init__.py", line 126, in import_module
    return _bootstrap._gcd_import(name[level:], package, level)
           ^^^^^^^^^^^^^^^^^^^^^^^^^^^^^^^^^^^^^^^^^^^^^^^^^^^^
  File "<frozen importlib._bootstrap>", line 1204, in _gcd_import
  File "<frozen importlib._bootstrap>", line 1176, in _find_and_load
  File "<frozen importlib._bootstrap>", line 1126, in _find_and_load_unlocked
  File "<frozen importlib._bootstrap>", line 241, in _call_with_frames_removed
  File "<frozen importlib._bootstrap>", line 1204, in _gcd_import
  File "<frozen importlib._bootstrap>", line 1176, in _find_and_load
  File "<frozen importlib._bootstrap>", line 1140, in _find_and_load_unlocked
ModuleNotFoundError: No module named 'senac'

During handling of the above exception, another exception occurred:

Traceback (most recent call last):
  File "C:\Users\51129532024.4\Desktop\curso-python\back-end\maquina_virtual\senac\manage.py", line 22, in <module>
    main()
  File "C:\Users\51129532024.4\Desktop\curso-python\back-end\maquina_virtual\senac\manage.py", line 18, in main
    execute_from_command_line(sys.argv)
  File "C:\Users\51129532024.4\Desktop\curso-python\back-end\maquina_virtual\.venv\Lib\site-packages\django\core\management\__init__.py", line 442, in execute_from_command_line
    utility.execute()
  File "C:\Users\51129532024.4\Desktop\curso-python\back-end\maquina_virtual\.venv\Lib\site-packages\django\core\management\__init__.py", line 436, in execute
    self.fetch_command(subcommand).run_from_argv(self.argv)
  File "C:\Users\51129532024.4\Desktop\curso-python\back-end\maquina_virtual\.venv\Lib\site-packages\django\core\management\base.py", line 426, in run_from_argv
    connections.close_all()
  File "C:\Users\51129532024.4\Desktop\curso-python\back-end\maquina_virtual\.venv\Lib\site-packages\django\utils\connection.py", line 84, in close_all
    for conn in self.all(initialized_only=True):
                ^^^^^^^^^^^^^^^^^^^^^^^^^^^^^^^
  File "C:\Users\51129532024.4\Desktop\curso-python\back-end\maquina_virtual\.venv\Lib\site-packages\django\utils\connection.py", line 76, in all
    return [
           ^
  File "C:\Users\51129532024.4\Desktop\curso-python\back-end\maquina_virtual\.venv\Lib\site-packages\django\utils\connection.py", line 73, in __iter__
    return iter(self.settings)
                ^^^^^^^^^^^^^
  File "C:\Users\51129532024.4\Desktop\curso-python\back-end\maquina_virtual\.venv\Lib\site-packages\django\utils\functional.py", line 47, in __get__
    res = instance.__dict__[self.name] = self.func(instance)
                                         ^^^^^^^^^^^^^^^^^^^
  File "C:\Users\51129532024.4\Desktop\curso-python\back-end\maquina_virtual\.venv\Lib\site-packages\django\utils\connection.py", line 45, in settings
    self._settings = self.configure_settings(self._settings)
                     ^^^^^^^^^^^^^^^^^^^^^^^^^^^^^^^^^^^^^^^
  File "C:\Users\51129532024.4\Desktop\curso-python\back-end\maquina_virtual\.venv\Lib\site-packages\django\db\utils.py", line 148, in configure_settings
    databases = super().configure_settings(databases)
                ^^^^^^^^^^^^^^^^^^^^^^^^^^^^^^^^^^^^^
  File "C:\Users\51129532024.4\Desktop\curso-python\back-end\maquina_virtual\.venv\Lib\site-packages\django\utils\connection.py", line 50, in configure_settings
    settings = getattr(django_settings, self.settings_name)
               ^^^^^^^^^^^^^^^^^^^^^^^^^^^^^^^^^^^^^^^^^^^^
  File "C:\Users\51129532024.4\Desktop\curso-python\back-end\maquina_virtual\.venv\Lib\site-packages\django\conf\__init__.py", line 81, in __getattr__
    self._setup(name)
  File "C:\Users\51129532024.4\Desktop\curso-python\back-end\maquina_virtual\.venv\Lib\site-packages\django\conf\__init__.py", line 68, in _setup
    self._wrapped = Settings(settings_module)
                    ^^^^^^^^^^^^^^^^^^^^^^^^^
  File "C:\Users\51129532024.4\Desktop\curso-python\back-end\maquina_virtual\.venv\Lib\site-packages\django\conf\__init__.py", line 166, in __init__
    mod = importlib.import_module(self.SETTINGS_MODULE)
          ^^^^^^^^^^^^^^^^^^^^^^^^^^^^^^^^^^^^^^^^^^^^^
  File "C:\Program Files\Python311\Lib\importlib\__init__.py", line 126, in import_module
    return _bootstrap._gcd_import(name[level:], package, level)
           ^^^^^^^^^^^^^^^^^^^^^^^^^^^^^^^^^^^^^^^^^^^^^^^^^^^^
  File "<frozen importlib._bootstrap>", line 1204, in _gcd_import
  File "<frozen importlib._bootstrap>", line 1176, in _find_and_load
  File "<frozen importlib._bootstrap>", line 1126, in _find_and_load_unlocked
  File "<frozen importlib._bootstrap>", line 241, in _call_with_frames_removed
  File "<frozen importlib._bootstrap>", line 1204, in _gcd_import
  File "<frozen importlib._bootstrap>", line 1176, in _find_and_load
  File "<frozen importlib._bootstrap>", line 1140, in _find_and_load_unlocked
ModuleNotFoundError: No module named 'senac'
(.venv) PS C:\Users\51129532024.4\Desktop\curso-python\back-end\maquina_virtual\senac> cd senac_project          
cd : Não é possível localizar o caminho 'C:\Users\51129532024.4\Desktop\curso-python\back-end\maquina_virtual\senac\senac_project' porque ele não existe.
No linha:1 caractere:1
+ cd senac_project
+ ~~~~~~~~~~~~~~~~
    + FullyQualifiedErrorId : PathNotFound,Microsoft.PowerShell.Commands.SetLocationCommand
 
(.venv) PS C:\Users\51129532024.4\Desktop\curso-python\back-end\maquina_virtual\senac> ls


    Diretório: C:\Users\51129532024.4\Desktop\curso-python\back-end\maquina_virtual\senac


Mode                 LastWriteTime         Length Name                                                                                                                                                                      
----                 -------------         ------ ----                                                                                                                                                                      
d-----        17/01/2025     19:51                senac_projeto                                                                                                                                                             
-a----        17/01/2025     19:51              0 db.sqlite3                                                                                                                                                                

(.venv) PS C:\Users\51129532024.4\Desktop\curso-python\back-end\maquina_virtual\senac> cd .\senac_projeto\
(.venv) PS C:\Users\51129532024.4\Desktop\curso-python\back-end\maquina_virtual\senac\senac_projeto> python manage.py runserver
C:\Program Files\Python311\python.exe: can't open file 'C:\\Users\\51129532024.4\\Desktop\\curso-python\\back-end\\maquina_virtual\\senac\\senac_projeto\\manage.py': [Errno 2] No such file or directory
(.venv) PS C:\Users\51129532024.4\Desktop\curso-python\back-end\maquina_virtual\senac\senac_projeto> python manage.py runserver
(.venv) PS C:\Users\51129532024.4\Desktop\curso-python\back-end\maquina_virtual\senac\senac_projeto> cd ..
(.venv) PS C:\Users\51129532024.4\Desktop\curso-python\back-end\maquina_virtual\senac> python manage.py runserver
Watching for file changes with StatReloader
Performing system checks...

System check identified no issues (0 silenced).

You have 18 unapplied migration(s). Your project may not work properly until you apply the migrations for app(s): admin, auth, contenttypes, sessions.
January 17, 2025 - 20:38:07
Django version 5.1.5, using settings 'senac.settings'
Quit the server with CTRL-BREAK.

[17/Jan/2025 20:38:12] "GET / HTTP/1.1" 200 12068
(.venv) PS C:\Users\51129532024.4\Desktop\curso-python\back-end\maquina_virtual\senac> python manage.py runserver
Watching for file changes with StatReloader
Performing system checks...

System check identified no issues (0 silenced).

You have 18 unapplied migration(s). Your project may not work properly until you apply the migrations for app(s): admin, auth, contenttypes, sessions.
Run 'python manage.py migrate' to apply them.
January 17, 2025 - 20:41:30
Django version 5.1.5, using settings 'senac.settings'
Starting development server at http://127.0.0.1:8000/
Quit the server with CTRL-BREAK.

(.venv) PS C:\Users\51129532024.4\Desktop\curso-python\back-end\maquina_virtual\senac> python manage.py startapp marcador_de_data 
(.venv) PS C:\Users\51129532024.4\Desktop\curso-python\back-end\maquina_virtual\senac> python manage.py runserver
Watching for file changes with StatReloader
Performing system checks...


You have 18 unapplied migration(s). Your project may not work properly until you apply the migrations for app(s): admin, auth, contenttypes, sessions.
Run 'python manage.py migrate' to apply them.
January 17, 2025 - 20:50:33
Django version 5.1.5, using settings 'senac.settings'
Starting development server at http://127.0.0.1:8000/
Quit the server with CTRL-BREAK.

[17/Jan/2025 20:50:37] "GET / HTTP/1.1" 200 12068
(.venv) PS C:\Users\51129532024.4\Desktop\curso-python\back-end\maquina_virtual\senac> python manage.py migration
Unknown command: 'migration'. Did you mean showmigrations?
Type 'manage.py help' for usage.
(.venv) PS C:\Users\51129532024.4\Desktop\curso-python\back-end\maquina_virtual\senac> python manage.py migrate  
Operations to perform:
  Apply all migrations: admin, auth, contenttypes, sessions
Running migrations:
  Applying contenttypes.0001_initial... OK
  Applying auth.0001_initial... OK
  Applying admin.0001_initial... OK
  Applying admin.0002_logentry_remove_auto_add... OK
  Applying admin.0003_logentry_add_action_flag_choices... OK
  Applying auth.0002_alter_permission_name_max_length... OK
  Applying auth.0004_alter_user_username_opts... OK
  Applying auth.0005_alter_user_last_login_null... OK
  Applying auth.0006_require_contenttypes_0002... OK
  Applying auth.0007_alter_validators_add_error_messages... OK
  Applying auth.0008_alter_user_username_max_length... OK
  Applying auth.0009_alter_user_last_name_max_length... OK
  Applying auth.0010_alter_group_name_max_length... OK
  Applying auth.0011_update_proxy_permissions... OK
  Applying auth.0012_alter_user_first_name_max_length... OK
  Applying sessions.0001_initial... OK
(.venv) PS C:\Users\51129532024.4\Desktop\curso-python\back-end\maquina_virtual\senac> python manage.py runserver
Performing system checks...

System check identified no issues (0 silenced).
January 17, 2025 - 21:00:03
Django version 5.1.5, using settings 'senac.settings'
Starting development server at http://127.0.0.1:8000/
Quit the server with CTRL-BREAK.

[17/Jan/2025 21:00:06] "GET / HTTP/1.1" 200 12068
[17/Jan/2025 21:00:37] "GET /admin HTTP/1.1" 301 0
[17/Jan/2025 21:00:37] "GET /admin/ HTTP/1.1" 302 0
[17/Jan/2025 21:00:37] "GET /admin/login/?next=/admin/ HTTP/1.1" 200 4160
[17/Jan/2025 21:00:38] "GET /static/admin/css/nav_sidebar.css HTTP/1.1" 200 2810
[17/Jan/2025 21:00:38] "GET /static/admin/css/base.css HTTP/1.1" 200 22092
[17/Jan/2025 21:00:38] "GET /static/admin/js/theme.js HTTP/1.1" 200 1653
[17/Jan/2025 21:00:38] "GET /static/admin/css/responsive.css HTTP/1.1" 200 17972
[17/Jan/2025 21:00:38] "GET /static/admin/css/dark_mode.css HTTP/1.1" 200 2804
[17/Jan/2025 21:00:38] "GET /static/admin/js/nav_sidebar.js HTTP/1.1" 200 3063
[17/Jan/2025 21:00:38] "GET /static/admin/css/login.css HTTP/1.1" 200 951
[17/Jan/2025 21:02:14] "POST /admin/login/?next=/admin/ HTTP/1.1" 200 4328
(.venv) PS C:\Users\51129532024.4\Desktop\curso-python\back-end\maquina_virtual\senac> python createsuperuser
C:\Program Files\Python311\python.exe: can't open file 'C:\\Users\\51129532024.4\\Desktop\\curso-python\\back-end\\maquina_virtual\\senac\\createsuperuser': [Errno 2] No such file or directory
(.venv) PS C:\Users\51129532024.4\Desktop\curso-python\back-end\maquina_virtual\senac> python manage.py createsuperuser
Username (leave blank to use '51129532024.4'): admin
Email address: juandesouzacardoso@outlook.com
Password:
Password (again):
The password is too similar to the username.
This password is too short. It must contain at least 8 characters.
This password is too common.
The password is too similar to the username.
This password is too short. It must contain at least 8 characters.
This password is too common.
Bypass password validation and create user anyway? [y/N]: N
Bypass password validation and create user anyway? [y/N]: N
Password:
Password (again):
Password:
Password (again):
Superuser created successfully.
Superuser created successfully.
(.venv) PS C:\Users\51129532024.4\Desktop\curso-python\back-end\maquina_virtual\senac> python manage.py runserver
Watching for file changes with StatReloader
Performing system checks...

System check identified no issues (0 silenced).
(.venv) PS C:\Users\51129532024.4\Desktop\curso-python\back-end\maquina_virtual\senac> python manage.py runserver
Watching for file changes with StatReloader
Performing system checks...

System check identified no issues (0 silenced).
Performing system checks...

System check identified no issues (0 silenced).

System check identified no issues (0 silenced).
January 17, 2025 - 21:22:12
January 17, 2025 - 21:22:12
Django version 5.1.5, using settings 'senac.settings'
Starting development server at http://127.0.0.1:8000/
Django version 5.1.5, using settings 'senac.settings'
Starting development server at http://127.0.0.1:8000/
Quit the server with CTRL-BREAK.

[17/Jan/2025 21:22:15] "GET / HTTP/1.1" 200 12068
Quit the server with CTRL-BREAK.

[17/Jan/2025 21:22:15] "GET / HTTP/1.1" 200 12068
[17/Jan/2025 21:22:22] "GET /admin/ HTTP/1.1" 302 0
[17/Jan/2025 21:22:22] "GET /admin/login/?next=/admin/ HTTP/1.1" 200 4160
[17/Jan/2025 21:22:22] "GET /admin/ HTTP/1.1" 302 0
[17/Jan/2025 21:22:22] "GET /admin/login/?next=/admin/ HTTP/1.1" 200 4160
[17/Jan/2025 21:22:22] "GET /static/admin/css/base.css HTTP/1.1" 304 0
[17/Jan/2025 21:22:22] "GET /static/admin/css/dark_mode.css HTTP/1.1" 304 0
[17/Jan/2025 21:22:22] "GET /static/admin/css/nav_sidebar.css HTTP/1.1" 304 0
[17/Jan/2025 21:22:22] "GET /static/admin/css/base.css HTTP/1.1" 304 0
[17/Jan/2025 21:22:22] "GET /static/admin/css/dark_mode.css HTTP/1.1" 304 0
[17/Jan/2025 21:22:22] "GET /static/admin/css/nav_sidebar.css HTTP/1.1" 304 0
[17/Jan/2025 21:22:22] "GET /static/admin/css/login.css HTTP/1.1" 304 0
[17/Jan/2025 21:22:22] "GET /static/admin/css/login.css HTTP/1.1" 304 0
[17/Jan/2025 21:22:22] "GET /static/admin/css/responsive.css HTTP/1.1" 304 0
[17/Jan/2025 21:22:22] "GET /static/admin/css/responsive.css HTTP/1.1" 304 0
[17/Jan/2025 21:22:22] "GET /static/admin/js/theme.js HTTP/1.1" 304 0
[17/Jan/2025 21:22:22] "GET /static/admin/js/nav_sidebar.js HTTP/1.1" 304 0
[17/Jan/2025 21:22:34] "POST /admin/login/?next=/admin/ HTTP/1.1" 302 0
[17/Jan/2025 21:22:34] "GET /admin/ HTTP/1.1" 200 5852
[17/Jan/2025 21:22:35] "GET /static/admin/css/dashboard.css HTTP/1.1" 200 441
[17/Jan/2025 21:22:35] "GET /static/admin/img/icon-addlink.svg HTTP/1.1" 200 331
[17/Jan/2025 21:22:35] "GET /static/admin/img/icon-changelink.svg HTTP/1.1" 200 380
C:\Users\51129532024.4\Desktop\curso-python\back-end\maquina_virtual\senac\senac\settings.py changed, reloading.
Watching for file changes with StatReloader
Exception in thread django-main-thread:
Traceback (most recent call last):
  File "C:\Program Files\Python311\Lib\threading.py", line 1038, in _bootstrap_inner
    self.run()
  File "C:\Program Files\Python311\Lib\threading.py", line 975, in run
    self._target(*self._args, **self._kwargs)
  File "C:\Users\51129532024.4\Desktop\curso-python\back-end\maquina_virtual\.venv\Lib\site-packages\django\utils\autoreload.py", line 64, in wrapper
    fn(*args, **kwargs)
  File "C:\Users\51129532024.4\Desktop\curso-python\back-end\maquina_virtual\.venv\Lib\site-packages\django\core\management\commands\runserver.py", line 126, in inner_run
    autoreload.raise_last_exception()
  File "C:\Users\51129532024.4\Desktop\curso-python\back-end\maquina_virtual\.venv\Lib\site-packages\django\utils\autoreload.py", line 87, in raise_last_exception
    raise _exception[1]
  File "C:\Users\51129532024.4\Desktop\curso-python\back-end\maquina_virtual\.venv\Lib\site-packages\django\core\management\__init__.py", line 394, in execute
    autoreload.check_errors(django.setup)()
  File "C:\Users\51129532024.4\Desktop\curso-python\back-end\maquina_virtual\.venv\Lib\site-packages\django\utils\autoreload.py", line 64, in wrapper
    fn(*args, **kwargs)
  File "C:\Users\51129532024.4\Desktop\curso-python\back-end\maquina_virtual\.venv\Lib\site-packages\django\__init__.py", line 24, in setup
    apps.populate(settings.INSTALLED_APPS)
  File "C:\Users\51129532024.4\Desktop\curso-python\back-end\maquina_virtual\.venv\Lib\site-packages\django\apps\registry.py", line 116, in populate
    app_config.import_models()
  File "C:\Users\51129532024.4\Desktop\curso-python\back-end\maquina_virtual\.venv\Lib\site-packages\django\apps\config.py", line 269, in import_models
    self.models_module = import_module(models_module_name)
                         ^^^^^^^^^^^^^^^^^^^^^^^^^^^^^^^^^
  File "C:\Program Files\Python311\Lib\importlib\__init__.py", line 126, in import_module
    return _bootstrap._gcd_import(name[level:], package, level)
           ^^^^^^^^^^^^^^^^^^^^^^^^^^^^^^^^^^^^^^^^^^^^^^^^^^^^
  File "<frozen importlib._bootstrap>", line 1204, in _gcd_import
  File "<frozen importlib._bootstrap>", line 1176, in _find_and_load
  File "<frozen importlib._bootstrap>", line 1147, in _find_and_load_unlocked
  File "<frozen importlib._bootstrap>", line 690, in _load_unlocked
  File "<frozen importlib._bootstrap_external>", line 940, in exec_module
  File "<frozen importlib._bootstrap>", line 241, in _call_with_frames_removed
  File "C:\Users\51129532024.4\Desktop\curso-python\back-end\maquina_virtual\.venv\Lib\site-packages\django\contrib\auth\models.py", line 99, in <module>
    class Group(models.Model):
  File "C:\Users\51129532024.4\Desktop\curso-python\back-end\maquina_virtual\.venv\Lib\site-packages\django\db\models\base.py", line 194, in __new__
    new_class.add_to_class(obj_name, obj)
  File "C:\Users\51129532024.4\Desktop\curso-python\back-end\maquina_virtual\.venv\Lib\site-packages\django\db\models\base.py", line 371, in add_to_class
    value.contribute_to_class(cls, name)
  File "C:\Users\51129532024.4\Desktop\curso-python\back-end\maquina_virtual\.venv\Lib\site-packages\django\db\models\fields\related.py", line 1926, in contribute_to_class
    self.remote_field.through = create_many_to_many_intermediary_model(
                                ^^^^^^^^^^^^^^^^^^^^^^^^^^^^^^^^^^^^^^^
  File "C:\Users\51129532024.4\Desktop\curso-python\back-end\maquina_virtual\.venv\Lib\site-packages\django\db\models\fields\related.py", line 1285, in create_many_to_many_intermediary_model
    "verbose_name": _("%(from)s-%(to)s relationship")
                    ^^^^^^^^^^^^^^^^^^^^^^^^^^^^^^^^^
  File "C:\Users\51129532024.4\Desktop\curso-python\back-end\maquina_virtual\.venv\Lib\site-packages\django\utils\functional.py", line 167, in __mod__
    return self.__cast() % other
           ^^^^^^^^^^^^^
  File "C:\Users\51129532024.4\Desktop\curso-python\back-end\maquina_virtual\.venv\Lib\site-packages\django\utils\functional.py", line 110, in __cast
    return func(*self._args, **self._kw)
           ^^^^^^^^^^^^^^^^^^^^^^^^^^^^^
  File "C:\Users\51129532024.4\Desktop\curso-python\back-end\maquina_virtual\.venv\Lib\site-packages\django\utils\translation\__init__.py", line 96, in gettext
    return _trans.gettext(message)
           ^^^^^^^^^^^^^^^^^^^^^^^
  File "C:\Users\51129532024.4\Desktop\curso-python\back-end\maquina_virtual\.venv\Lib\site-packages\django\utils\translation\trans_real.py", line 381, in gettext
    _default = _default or translation(settings.LANGUAGE_CODE)
                           ^^^^^^^^^^^^^^^^^^^^^^^^^^^^^^^^^^^
  File "C:\Users\51129532024.4\Desktop\curso-python\back-end\maquina_virtual\.venv\Lib\site-packages\django\utils\translation\trans_real.py", line 294, in translation
    _translations[language] = DjangoTranslation(language)
                              ^^^^^^^^^^^^^^^^^^^^^^^^^^^
  File "C:\Users\51129532024.4\Desktop\curso-python\back-end\maquina_virtual\.venv\Lib\site-packages\django\utils\translation\trans_real.py", line 180, in __init__
    raise OSError(
OSError: No translation files found for default language .
C:\Users\51129532024.4\Desktop\curso-python\back-end\maquina_virtual\senac\senac\settings.py changed, reloading.
Watching for file changes with StatReloader
Performing system checks...

System check identified no issues (0 silenced).
January 17, 2025 - 21:23:15
Django version 5.1.5, using settings 'senac.settings'
Starting development server at http://127.0.0.1:8000/
Quit the server with CTRL-BREAK.

C:\Users\51129532024.4\Desktop\curso-python\back-end\maquina_virtual\senac\senac\settings.py changed, reloading.
Watching for file changes with StatReloader
Exception in thread django-main-thread:
Traceback (most recent call last):
  File "C:\Program Files\Python311\Lib\threading.py", line 1038, in _bootstrap_inner
    self.run()
  File "C:\Program Files\Python311\Lib\threading.py", line 975, in run
    self._target(*self._args, **self._kwargs)
  File "C:\Users\51129532024.4\Desktop\curso-python\back-end\maquina_virtual\.venv\Lib\site-packages\django\utils\autoreload.py", line 64, in wrapper
    fn(*args, **kwargs)
  File "C:\Users\51129532024.4\Desktop\curso-python\back-end\maquina_virtual\.venv\Lib\site-packages\django\core\management\commands\runserver.py", line 126, in inner_run
    autoreload.raise_last_exception()
  File "C:\Users\51129532024.4\Desktop\curso-python\back-end\maquina_virtual\.venv\Lib\site-packages\django\utils\autoreload.py", line 87, in raise_last_exception
    raise _exception[1]
  File "C:\Users\51129532024.4\Desktop\curso-python\back-end\maquina_virtual\.venv\Lib\site-packages\django\core\management\__init__.py", line 394, in execute
    autoreload.check_errors(django.setup)()
  File "C:\Users\51129532024.4\Desktop\curso-python\back-end\maquina_virtual\.venv\Lib\site-packages\django\utils\autoreload.py", line 64, in wrapper
    fn(*args, **kwargs)
  File "C:\Users\51129532024.4\Desktop\curso-python\back-end\maquina_virtual\.venv\Lib\site-packages\django\__init__.py", line 24, in setup
    apps.populate(settings.INSTALLED_APPS)
  File "C:\Users\51129532024.4\Desktop\curso-python\back-end\maquina_virtual\.venv\Lib\site-packages\django\apps\registry.py", line 116, in populate
    app_config.import_models()
  File "C:\Users\51129532024.4\Desktop\curso-python\back-end\maquina_virtual\.venv\Lib\site-packages\django\apps\config.py", line 269, in import_models
    self.models_module = import_module(models_module_name)
                         ^^^^^^^^^^^^^^^^^^^^^^^^^^^^^^^^^
  File "C:\Program Files\Python311\Lib\importlib\__init__.py", line 126, in import_module
    return _bootstrap._gcd_import(name[level:], package, level)
           ^^^^^^^^^^^^^^^^^^^^^^^^^^^^^^^^^^^^^^^^^^^^^^^^^^^^
  File "<frozen importlib._bootstrap>", line 1204, in _gcd_import
  File "<frozen importlib._bootstrap>", line 1176, in _find_and_load
  File "<frozen importlib._bootstrap>", line 1147, in _find_and_load_unlocked
  File "<frozen importlib._bootstrap>", line 690, in _load_unlocked
  File "<frozen importlib._bootstrap_external>", line 940, in exec_module
  File "<frozen importlib._bootstrap>", line 241, in _call_with_frames_removed
  File "C:\Users\51129532024.4\Desktop\curso-python\back-end\maquina_virtual\.venv\Lib\site-packages\django\contrib\auth\models.py", line 99, in <module>
    class Group(models.Model):
  File "C:\Users\51129532024.4\Desktop\curso-python\back-end\maquina_virtual\.venv\Lib\site-packages\django\db\models\base.py", line 194, in __new__
    new_class.add_to_class(obj_name, obj)
  File "C:\Users\51129532024.4\Desktop\curso-python\back-end\maquina_virtual\.venv\Lib\site-packages\django\db\models\base.py", line 371, in add_to_class
    value.contribute_to_class(cls, name)
  File "C:\Users\51129532024.4\Desktop\curso-python\back-end\maquina_virtual\.venv\Lib\site-packages\django\db\models\fields\related.py", line 1926, in contribute_to_class
    self.remote_field.through = create_many_to_many_intermediary_model(
                                ^^^^^^^^^^^^^^^^^^^^^^^^^^^^^^^^^^^^^^^
  File "C:\Users\51129532024.4\Desktop\curso-python\back-end\maquina_virtual\.venv\Lib\site-packages\django\db\models\fields\related.py", line 1285, in create_many_to_many_intermediary_model
    "verbose_name": _("%(from)s-%(to)s relationship")
                    ^^^^^^^^^^^^^^^^^^^^^^^^^^^^^^^^^
  File "C:\Users\51129532024.4\Desktop\curso-python\back-end\maquina_virtual\.venv\Lib\site-packages\django\utils\functional.py", line 167, in __mod__
    return self.__cast() % other
           ^^^^^^^^^^^^^
  File "C:\Users\51129532024.4\Desktop\curso-python\back-end\maquina_virtual\.venv\Lib\site-packages\django\utils\functional.py", line 110, in __cast
    return func(*self._args, **self._kw)
           ^^^^^^^^^^^^^^^^^^^^^^^^^^^^^
  File "C:\Users\51129532024.4\Desktop\curso-python\back-end\maquina_virtual\.venv\Lib\site-packages\django\utils\translation\__init__.py", line 96, in gettext
    return _trans.gettext(message)
           ^^^^^^^^^^^^^^^^^^^^^^^
  File "C:\Users\51129532024.4\Desktop\curso-python\back-end\maquina_virtual\.venv\Lib\site-packages\django\utils\translation\trans_real.py", line 381, in gettext
    _default = _default or translation(settings.LANGUAGE_CODE)
                           ^^^^^^^^^^^^^^^^^^^^^^^^^^^^^^^^^^^
  File "C:\Users\51129532024.4\Desktop\curso-python\back-end\maquina_virtual\.venv\Lib\site-packages\django\utils\translation\trans_real.py", line 294, in translation
    _translations[language] = DjangoTranslation(language)
                              ^^^^^^^^^^^^^^^^^^^^^^^^^^^
  File "C:\Users\51129532024.4\Desktop\curso-python\back-end\maquina_virtual\.venv\Lib\site-packages\django\utils\translation\trans_real.py", line 180, in __init__
    raise OSError(
OSError: No translation files found for default language .
C:\Users\51129532024.4\Desktop\curso-python\back-end\maquina_virtual\senac\senac\settings.py changed, reloading.
Watching for file changes with StatReloader
Performing system checks...

System check identified no issues (0 silenced).
January 17, 2025 - 21:23:18
Django version 5.1.5, using settings 'senac.settings'
Starting development server at http://127.0.0.1:8000/
Quit the server with CTRL-BREAK.

C:\Users\51129532024.4\Desktop\curso-python\back-end\maquina_virtual\senac\senac\settings.py changed, reloading.
Watching for file changes with StatReloader
Exception in thread django-main-thread:
Traceback (most recent call last):
  File "C:\Program Files\Python311\Lib\threading.py", line 1038, in _bootstrap_inner
    self.run()
  File "C:\Program Files\Python311\Lib\threading.py", line 975, in run
    self._target(*self._args, **self._kwargs)
  File "C:\Users\51129532024.4\Desktop\curso-python\back-end\maquina_virtual\.venv\Lib\site-packages\django\utils\autoreload.py", line 64, in wrapper
    fn(*args, **kwargs)
  File "C:\Users\51129532024.4\Desktop\curso-python\back-end\maquina_virtual\.venv\Lib\site-packages\django\core\management\commands\runserver.py", line 126, in inner_run
    autoreload.raise_last_exception()
  File "C:\Users\51129532024.4\Desktop\curso-python\back-end\maquina_virtual\.venv\Lib\site-packages\django\utils\autoreload.py", line 87, in raise_last_exception
    raise _exception[1]
  File "C:\Users\51129532024.4\Desktop\curso-python\back-end\maquina_virtual\.venv\Lib\site-packages\django\core\management\__init__.py", line 394, in execute
    autoreload.check_errors(django.setup)()
  File "C:\Users\51129532024.4\Desktop\curso-python\back-end\maquina_virtual\.venv\Lib\site-packages\django\utils\autoreload.py", line 64, in wrapper
    fn(*args, **kwargs)
  File "C:\Users\51129532024.4\Desktop\curso-python\back-end\maquina_virtual\.venv\Lib\site-packages\django\__init__.py", line 24, in setup
    apps.populate(settings.INSTALLED_APPS)
  File "C:\Users\51129532024.4\Desktop\curso-python\back-end\maquina_virtual\.venv\Lib\site-packages\django\apps\registry.py", line 116, in populate
    app_config.import_models()
  File "C:\Users\51129532024.4\Desktop\curso-python\back-end\maquina_virtual\.venv\Lib\site-packages\django\apps\config.py", line 269, in import_models
    self.models_module = import_module(models_module_name)
                         ^^^^^^^^^^^^^^^^^^^^^^^^^^^^^^^^^
  File "C:\Program Files\Python311\Lib\importlib\__init__.py", line 126, in import_module
    return _bootstrap._gcd_import(name[level:], package, level)
           ^^^^^^^^^^^^^^^^^^^^^^^^^^^^^^^^^^^^^^^^^^^^^^^^^^^^
  File "<frozen importlib._bootstrap>", line 1204, in _gcd_import
  File "<frozen importlib._bootstrap>", line 1176, in _find_and_load
  File "<frozen importlib._bootstrap>", line 1147, in _find_and_load_unlocked
  File "<frozen importlib._bootstrap>", line 690, in _load_unlocked
  File "<frozen importlib._bootstrap_external>", line 940, in exec_module
  File "<frozen importlib._bootstrap>", line 241, in _call_with_frames_removed
  File "C:\Users\51129532024.4\Desktop\curso-python\back-end\maquina_virtual\.venv\Lib\site-packages\django\contrib\auth\models.py", line 99, in <module>
    class Group(models.Model):
  File "C:\Users\51129532024.4\Desktop\curso-python\back-end\maquina_virtual\.venv\Lib\site-packages\django\db\models\base.py", line 194, in __new__
    new_class.add_to_class(obj_name, obj)
  File "C:\Users\51129532024.4\Desktop\curso-python\back-end\maquina_virtual\.venv\Lib\site-packages\django\db\models\base.py", line 371, in add_to_class
    value.contribute_to_class(cls, name)
  File "C:\Users\51129532024.4\Desktop\curso-python\back-end\maquina_virtual\.venv\Lib\site-packages\django\db\models\fields\related.py", line 1926, in contribute_to_class
    self.remote_field.through = create_many_to_many_intermediary_model(
                                ^^^^^^^^^^^^^^^^^^^^^^^^^^^^^^^^^^^^^^^
  File "C:\Users\51129532024.4\Desktop\curso-python\back-end\maquina_virtual\.venv\Lib\site-packages\django\db\models\fields\related.py", line 1285, in create_many_to_many_intermediary_model
    "verbose_name": _("%(from)s-%(to)s relationship")
                    ^^^^^^^^^^^^^^^^^^^^^^^^^^^^^^^^^
  File "C:\Users\51129532024.4\Desktop\curso-python\back-end\maquina_virtual\.venv\Lib\site-packages\django\utils\functional.py", line 167, in __mod__
    return self.__cast() % other
           ^^^^^^^^^^^^^
  File "C:\Users\51129532024.4\Desktop\curso-python\back-end\maquina_virtual\.venv\Lib\site-packages\django\utils\functional.py", line 110, in __cast
    return func(*self._args, **self._kw)
           ^^^^^^^^^^^^^^^^^^^^^^^^^^^^^
  File "C:\Users\51129532024.4\Desktop\curso-python\back-end\maquina_virtual\.venv\Lib\site-packages\django\utils\translation\__init__.py", line 96, in gettext
    return _trans.gettext(message)
           ^^^^^^^^^^^^^^^^^^^^^^^
  File "C:\Users\51129532024.4\Desktop\curso-python\back-end\maquina_virtual\.venv\Lib\site-packages\django\utils\translation\trans_real.py", line 381, in gettext
    _default = _default or translation(settings.LANGUAGE_CODE)
                           ^^^^^^^^^^^^^^^^^^^^^^^^^^^^^^^^^^^
  File "C:\Users\51129532024.4\Desktop\curso-python\back-end\maquina_virtual\.venv\Lib\site-packages\django\utils\translation\trans_real.py", line 294, in translation
    _translations[language] = DjangoTranslation(language)
                              ^^^^^^^^^^^^^^^^^^^^^^^^^^^
  File "C:\Users\51129532024.4\Desktop\curso-python\back-end\maquina_virtual\.venv\Lib\site-packages\django\utils\translation\trans_real.py", line 180, in __init__
    raise OSError(
OSError: No translation files found for default language pt-.
C:\Users\51129532024.4\Desktop\curso-python\back-end\maquina_virtual\senac\senac\settings.py changed, reloading.
Watching for file changes with StatReloader
Performing system checks...

System check identified no issues (0 silenced).
January 17, 2025 - 21:23:22
Django version 5.1.5, using settings 'senac.settings'
Starting development server at http://127.0.0.1:8000/
Quit the server with CTRL-BREAK.

C:\Users\51129532024.4\Desktop\curso-python\back-end\maquina_virtual\senac\senac\settings.py changed, reloading.
Watching for file changes with StatReloader
Performing system checks...

System check identified no issues (0 silenced).
January 17, 2025 - 21:23:29
Django version 5.1.5, using settings 'senac.settings'
Starting development server at http://127.0.0.1:8000/
Quit the server with CTRL-BREAK.

C:\Users\51129532024.4\Desktop\curso-python\back-end\maquina_virtual\senac\senac\settings.py changed, reloading.
Watching for file changes with StatReloader
Performing system checks...

System check identified no issues (0 silenced).
January 17, 2025 - 21:23:37
Django version 5.1.5, using settings 'senac.settings'
Starting development server at http://127.0.0.1:8000/
Quit the server with CTRL-BREAK.

C:\Users\51129532024.4\Desktop\curso-python\back-end\maquina_virtual\senac\senac\settings.py changed, reloading.
Watching for file changes with StatReloader
Performing system checks...

System check identified no issues (0 silenced).
January 17, 2025 - 21:23:40
Django version 5.1.5, using settings 'senac.settings'
Starting development server at http://127.0.0.1:8000/
Quit the server with CTRL-BREAK.

C:\Users\51129532024.4\Desktop\curso-python\back-end\maquina_virtual\senac\senac\settings.py changed, reloading.
Watching for file changes with StatReloader
Performing system checks...

System check identified no issues (0 silenced).
January 17, 2025 - 21:23:44
Django version 5.1.5, using settings 'senac.settings'
Starting development server at http://127.0.0.1:8000/
Quit the server with CTRL-BREAK.

C:\Users\51129532024.4\Desktop\curso-python\back-end\maquina_virtual\senac\senac\settings.py changed, reloading.
Watching for file changes with StatReloader
Performing system checks...

System check identified no issues (0 silenced).
January 17, 2025 - 21:23:45
Django version 5.1.5, using settings 'senac.settings'
Starting development server at http://127.0.0.1:8000/
Quit the server with CTRL-BREAK.

C:\Users\51129532024.4\Desktop\curso-python\back-end\maquina_virtual\senac\senac\settings.py changed, reloading.
Watching for file changes with StatReloader
Performing system checks...

System check identified no issues (0 silenced).
January 17, 2025 - 21:23:49
Django version 5.1.5, using settings 'senac.settings'
Starting development server at http://127.0.0.1:8000/
Quit the server with CTRL-BREAK.

C:\Users\51129532024.4\Desktop\curso-python\back-end\maquina_virtual\senac\senac\settings.py changed, reloading.
Watching for file changes with StatReloader
Performing system checks...

System check identified no issues (0 silenced).
January 17, 2025 - 21:23:54
Django version 5.1.5, using settings 'senac.settings'
Starting development server at http://127.0.0.1:8000/
Quit the server with CTRL-BREAK.

C:\Users\51129532024.4\Desktop\curso-python\back-end\maquina_virtual\senac\senac\settings.py changed, reloading.
Watching for file changes with StatReloader
Performing system checks...

System check identified no issues (0 silenced).
January 17, 2025 - 21:23:55
Django version 5.1.5, using settings 'senac.settings'
Starting development server at http://127.0.0.1:8000/
Quit the server with CTRL-BREAK.

C:\Users\51129532024.4\Desktop\curso-python\back-end\maquina_virtual\senac\senac\settings.py changed, reloading.
Watching for file changes with StatReloader
Performing system checks...

System check identified no issues (0 silenced).
January 17, 2025 - 21:23:57
Django version 5.1.5, using settings 'senac.settings'
Starting development server at http://127.0.0.1:8000/
Quit the server with CTRL-BREAK.

C:\Users\51129532024.4\Desktop\curso-python\back-end\maquina_virtual\senac\senac\settings.py changed, reloading.
Watching for file changes with StatReloader
Performing system checks...

System check identified no issues (0 silenced).
January 17, 2025 - 21:23:58
Django version 5.1.5, using settings 'senac.settings'
Starting development server at http://127.0.0.1:8000/
Quit the server with CTRL-BREAK.

C:\Users\51129532024.4\Desktop\curso-python\back-end\maquina_virtual\senac\senac\settings.py changed, reloading.
Watching for file changes with StatReloader
Performing system checks...

System check identified no issues (0 silenced).
January 17, 2025 - 21:24:01
Django version 5.1.5, using settings 'senac.settings'
Starting development server at http://127.0.0.1:8000/
Quit the server with CTRL-BREAK.

C:\Users\51129532024.4\Desktop\curso-python\back-end\maquina_virtual\senac\senac\settings.py changed, reloading.
Watching for file changes with StatReloader
Performing system checks...

System check identified no issues (0 silenced).
January 17, 2025 - 21:24:10
Django version 5.1.5, using settings 'senac.settings'
Starting development server at http://127.0.0.1:8000/
Quit the server with CTRL-BREAK.

[17/Jan/2025 21:24:16] "GET / HTTP/1.1" 200 12099
[17/Jan/2025 21:24:22] "GET /admin/ HTTP/1.1" 200 5935